<robot name="mycar_text">
    <!-- 底盘 -->
    <link name="base_link">
            <visual>
                <geometry>
                    <box size="0.86 0.60 0.25" />
                </geometry>
                    <origin xyz="0 0 0.125" rpy="0 0 0" />
                    <material name="car_color">
                        <color rgba="1 0 0 0.5"/>
                    </material>
            </visual>
    </link>
    <!-- 摄像头 -->
    <link name="camera">
        <visual>
            <geometry>
                <box size="0.02 0.05 0.05" />
            </geometry>
                <origin xyz="-0.01 0 0.025" rpy="0 0 0" />
                <material name="camera_color">
                    <color rgba="0 1 0 1"/>
                </material>
        </visual>
    </link>
    <!-- joint -->
    <joint name="camera2base" type="continuous">
        <parent link="base_link"/>
        <child link="camera"/>
        <origin xyz="0.35 0 0.25" rpy="0 0 0"/>
        <axis xyz="0 0 1"/>
    </joint>

</robot>